<mujoco>
    <compiler coordinate="local" angle="degree" inertiafromgeom="auto"/>
    <option timestep="0.0005" apirate="100" wind="0 0 0" density="1.2" viscosity="0" cone="elliptic"/>
    <worldbody>
        <light diffuse=".5 .5 .5" pos="0 0 3" dir="0 0 -1"/>
        <geom type="plane" pos="0 0 -0.325" size="10 10 0.1" contype="1" conaffinity="1"/>
        <body name="walls" pos="0 0 0">
            <geom type="box" pos="12.5 0 0" size="3 16 3" conaffinity="1" contype="1" condim="6"/>
            <geom type="box" pos="-12.5 0 0" size="3 16 3" conaffinity="1" contype="1" condim="6"/>
            <geom type="box" pos="0 12.5 0" size="10 3 3" conaffinity="1" contype="1" condim="6"/>
            <geom type="box" pos="0 -12.5 0" size="10 3 3" conaffinity="1" contype="1" condim="6"/>
            <geom type="box" pos="10.5 -10.5 0" size="3 3 3" euler="0 0 45" conaffinity="1" contype="1" condim="6"/>
            <geom type="box" pos="-10.5 10.5 0" size="3 3 3" euler="0 0 45" conaffinity="1" contype="1" condim="6"/>
            <geom type="box" pos="-10.5 -10.5 0" size="3 3 3" euler="0 0 45" conaffinity="1" contype="1" condim="6"/>
            <geom type="box" pos="10.5 10.5 0" size="3 3 3" euler="0 0 45" conaffinity="1" contype="1" condim="6"/>
        </body>
        <body name="Chaser" pos="5 0 0">
            <geom rgba="1 0 0 1" type="sphere" condim="6" size="1" conaffinity="1" contype="1"/>
            <joint name="cx" type="slide" pos="0 0 0" axis="1 0 0" range="-1 1" damping="1.0"/>
            <joint name="cy" type="slide" pos="0 0 0" axis="0 1 0" range="-1 1" damping="1.0"/>
        </body>
        <body name="Runner" pos="-5 0 0">
            <geom rgba="0 1 0 1" type="sphere" condim="6" size="1" conaffinity="1" contype="1"/>
            <joint name="rx" type="slide" pos="0 0 0" axis="1 0 0" range="-1 1" damping="1.0"/>
            <joint name="ry" type="slide" pos="0 0 0" axis="0 1 0" range="-1 1" damping="1.0"/>
        </body>
    </worldbody>
</mujoco>